Workbook

Sheet README
A1: 06 — Cost & Traceability Model (INR) — in-house commerce-intelligence app (Rama / Phoenix) — v0.3
A3: Purpose: editable planning model for build cost (labour by work package), CapEx-candidate / expense boundary, monthly OpEx, TCO (12/24/36 months), build-vs-buy vs Sellerboard, sensitivity and WP→release→feature traceability.
A5: Version 0.3 — audit cutoff 2026-10-10 (baseline v0.1 cutoff 2026-09-10). Scope source: /engineering/scope_register.json (36 work packages WP-01..WP-39 with WP-18/19/21 retired, 11,180 h; releases R0–R5 with calendar_weeks; 31 connectors; 172 features). Regenerate with /engineering/build_cost_model.py. Price sources: /research/public_sources_apis.md.
A7: ALL RATES AND ALLOWANCES ARE PLANNING ASSUMPTIONS, NOT QUOTES. No vendor, contractor or cloud provider has quoted these figures. Hourly rates are labelled assumptions for an Indian in-house / contract team; validate before approval.
A9: Colour legend: BLUE text = input / assumption you may change; BLACK text = formula (do not overwrite); GREEN text = link to another sheet; YELLOW fill = key decision inputs (contingency %, capitalization approved %, benefit threshold).
A11: How to change assumptions: edit BLUE cells on 'Assumptions' (rates, contingency, FTE capacity, FX, cloud, AI tokens, Sellerboard spend, scenario multipliers) and on 'WorkPackages' (hours per WP), and the category % inputs on 'Accounting_Boundary'. Every other sheet recalculates. Do not insert rows inside the rate table (rows referenced by VLOOKUP). To change scope, edit scope_register.json and re-run the build script.
A13: Sheets: Assumptions · WorkPackages · Build_Summary · Capacity_Schedule · OpEx_Monthly (with applies_from_release) · TCO · Accounting_Boundary · Build_vs_Buy · Sensitivity · Traceability · Features_Ref (data extract used by Traceability counts) · Verification (key totals, LibreOffice-recalc verified) · Change_v02_v03 (v0.2 vs v0.3 bridge and the WPs that drove it).
A15: Key conventions: hours × loaded rate = labour cost; cash TCO includes the 20% contingency as committed budget; it is shown separately in Build_Summary; 'Initial bounded release' = R0+R1 plus a pro-rata share of cross-cutting (ALL) WPs by hours; 'Full approved parity' = all WPs. Amortization is shown separately from cash and is never added to cash TCO. Capitalization is a CFO decision under Ind AS 38 / IAS 38 — default approved % is 0.
A17: What changed in v0.3 (2026-10-10, Owner decisions): (1) marketing function omitted — WP-18 review requests, WP-19 PPC analytics and WP-21 PPC automation retired; WP-14 reduced to LTV/repeat customers (220 h); WP-20 safety framework reduced to repricer writes (280 h); ad spend is still read (WP-37, R1) as a cost line so net profit matches Sellerboard. (2) All markets — every Amazon marketplace (new WP-38, R2) and Walmart/eBay/TikTok Shop (WP-23 moved R5→R2, 600 h); ops connectors split to new WP-39 (R5). (3) Build with ChatGPT Codex; deploy on AWS. R2 is now 'All markets & marketplaces' (14 weeks); R4 'Pricing automation (conditional)' (6 weeks); R5 10 weeks. See Change_v02_v03.
A18: Earlier — what changed in v0.2: R1 widened to 'India-first unified profit core' (14 weeks, was 10): WP-12 Shopify connector and WP-13 fee profiles moved R2→R1; new R1 WPs WP-31 (B2B sales), WP-32 (unified dashboard), WP-33 (mobile-first PWA shell), WP-34 (Sellerboard-compatible P&L + parallel run), WP-35 (Shopify cost completeness); new WP-36 (multi-entity consolidation) in R2; WP-24 reduced to 220 h. New OpEx line 'Courier/3PL data handling' (₹0 assumption, from R1). Sellerboard spend now 3 accounts on sellerboard.com + 1 Shopify store on sellerboard.io.
A19: Excluded from all figures: ad spend, stock purchases, fulfilment fees, GST/taxes on services, office overhead, recruitment. SP-API fees: Amazon cancelled the planned fees 'at this time' (May 2026) → $0 planning assumption, monitor.
A20: Sellerboard reference: sellerboard.com Business plan $39/mo observed (3 accounts); other .com plans $19–$79/mo per account. sellerboard.io (Shopify store, 1 store): plan NOT observed → $39/mo is an ASSUMPTION, labelled on Assumptions.

Sheet Assumptions
A1: Assumptions — all BLUE cells are planning assumptions, not quotes
A2: Units: INR unless stated. Cutoff 2026-10-10. Scope register v0.3.
A4: Loaded hourly rate by role (INR/h) | B4: Value | C4: Unit | D4: Note
A5: Solution architect | B5: 3500 | C5: INR/h | D5: Assumption — loaded (salary + overhead) India rate; not a quote
A6: Backend lead | B6: 3000 | C6: INR/h | D6: Assumption — loaded (salary + overhead) India rate; not a quote
A7: Backend | B7: 2400 | C7: INR/h | D7: Assumption — loaded (salary + overhead) India rate; not a quote
A8: Frontend | B8: 2200 | C8: INR/h | D8: Assumption — loaded (salary + overhead) India rate; not a quote
A9: Full-stack | B9: 2400 | C9: INR/h | D9: Assumption — loaded (salary + overhead) India rate; not a quote
A10: Integration eng | B10: 2600 | C10: INR/h | D10: Assumption — loaded (salary + overhead) India rate; not a quote
A11: Financial/data eng | B11: 2600 | C11: INR/h | D11: Assumption — loaded (salary + overhead) India rate; not a quote
A12: Data eng | B12: 2400 | C12: INR/h | D12: Assumption — loaded (salary + overhead) India rate; not a quote
A13: Product designer | B13: 2000 | C13: INR/h | D13: Assumption — loaded (salary + overhead) India rate; not a quote
A14: QA/security | B14: 1800 | C14: INR/h | D14: Assumption — loaded (salary + overhead) India rate; not a quote
A15: DevOps | B15: 2400 | C15: INR/h | D15: Assumption — loaded (salary + overhead) India rate; not a quote
A16: Delivery lead | B16: 3000 | C16: INR/h | D16: Assumption — loaded (salary + overhead) India rate; not a quote
A18: Delivery & capacity | B18: Value | C18: Unit | D18: Note
A19: Contingency % on labour | B19: 0.2 | C19: % | D19: Committed budget in cash TCO; shown separately in Build_Summary
A20: Nominal FTE capacity | B20: 160 | C20: h/month | D20: Assumption
A21: Productive factor | B21: 0.75 | C21: ratio | D21: Share of nominal hours that is productive delivery
A22: USD→INR | B22: 84 | C22: INR per USD | D22: Assumption; refresh at approval date
A23: Amortization period (capex-candidate) | B23: 3 | C23: years | D23: Straight-line; shown separately from cash
A25: Release calendar (from scope_register.json calendar_weeks) | B25: Value | C25: Unit | D25: Note
A26: R0 — Read-only pilot & foundations | B26: 8 | C26: weeks | D26: Workspace, entities, connectors read-only, raw ledger, 90-day backfill, no operational writes
A27: R1 — India-first unified profit core | B27: 14 | C27: weeks | D27: One dashboard for Amazon.in + Shopify India + manual B2B: Sellerboard-compatible P&L, COGS, fees, expenses, B2B entry, reports, mobile-first UI, parallel-run reconciliation
A28: R2 — All markets & marketplaces | B28: 14 | C28: weeks | D28: UK/US/FR/DE entities and stores, every other Amazon marketplace (NA/EU/FE regions), Walmart US/CA/MX, eBay, TikTok Shop; multi-entity consolidation with FX & intercompany elimination; LTV & repeat customers; B2B receivables/export
A29: R3 — Operations | B29: 10 | C29: weeks | D29: Inventory planner, POs, suppliers, FBA/WFS shipments, reimbursement candidates (Money Back), alerts, automation safety framework
A30: R4 — Pricing automation (conditional) | B30: 6 | C30: weeks | D30: Repricer contract (simulation-first; writes only after approval, maker-checker, canary, kill switch)
A31: R5 — Extended operations connectors & clients | B31: 10 | C31: weeks | D31: ShipStation/Flexport/SFN/Veeqo/CJ connectors, PWA extras, browser extension, QuickBooks/Tally export & cashflow, optional AI explain layer
A32: ALL — cross-cutting (sum of R0–R5) | B32: =SUM(B26:B31) -> 62 | C32: weeks | D32: Formula: sum of release weeks
A34: Cloud hosting (monthly, INR) | B34: Value | C34: Unit | D34: Note
A35: Compute (app + workers) | B35: 45000 | C35: INR/mo | D35: Assumption
A36: Managed Postgres | B36: 25000 | C36: INR/mo | D36: Assumption
A37: Object storage | B37: 8000 | C37: INR/mo | D37: Assumption
A38: Jobs / queue | B38: 10000 | C38: INR/mo | D38: Assumption
A39: Egress | B39: 5000 | C39: INR/mo | D39: Assumption
A40: Observability | B40: 12000 | C40: INR/mo | D40: Assumption
A41: Backups / DR (cross-region copy to ap-south-2) | B41: 6000 | C41: INR/mo | D41: Assumption
A42: Security / landing zone (GuardDuty, Security Hub, Config, CloudTrail, WAF, KMS) | B42: 18000 | C42: INR/mo | D42: Assumption
A44: Ongoing staff / support | B44: Value | C44: Unit | D44: Note
A45: Support / maintenance FTE | B45: 1 | C45: FTE | D45: Assumption — one engineer part-allocated
...

Sheet WorkPackages
A1: Work packages — hours are BLUE inputs (from scope_register.json); rate via VLOOKUP on Assumptions; cost = hours × rate
A3: WP | B3: Name | C3: Release | D3: Owner role | E3: Hours | F3: Rate (INR/h) | G3: Cost (INR) | H3: Category | I3: Dependencies | J3: Calendar stage
A4: WP-01 | B4: Discovery, source audit, requirement freeze | C4: R0 | D4: Solution architect | E4: 160 | F4: =VLOOKUP(D4,Assumptions!$A$5:$B$16,2,FALSE()) -> 3500 | G4: =E4*F4 -> 560000 | H4: Discovery | I4: — | J4: =IF(C4="ALL","Cross-cutting — all releases",INDEX(Assumptions!$A$26:$A$32,MATCH(C4&" —*",Assumptions!$A$26:$A$32,0))&" ("&INDEX(Assumptions!$B$26:$B$32,MATCH(C4&" —*",Assumptions!$A$26:$A$32,0))&" wk)") -> R0 — Read-only pilot & foundations (8 wk)
A5: WP-02 | B5: UX design system, atlas, accessibility baseline | C5: R0 | D5: Product designer | E5: 240 | F5: =VLOOKUP(D5,Assumptions!$A$5:$B$16,2,FALSE()) -> 2000 | G5: =E5*F5 -> 480000 | H5: Design | I5: WP-01 | J5: =IF(C5="ALL","Cross-cutting — all releases",INDEX(Assumptions!$A$26:$A$32,MATCH(C5&" —*",Assumptions!$A$26:$A$32,0))&" ("&INDEX(Assumptions!$B$26:$B$32,MATCH(C5&" —*",Assumptions!$A$26:$A$32,0))&" wk)") -> R0 — Read-only pilot & foundations (8 wk)
A6: WP-03 | B6: Platform foundation: FastAPI, Postgres, queue, auth, RBAC, audit log, observability | C6: R0 | D6: Backend lead | E6: 420 | F6: =VLOOKUP(D6,Assumptions!$A$5:$B$16,2,FALSE()) -> 3000 | G6: =E6*F6 -> 1260000 | H6: Backend | I6: WP-01 | J6: =IF(C6="ALL","Cross-cutting — all releases",INDEX(Assumptions!$A$26:$A$32,MATCH(C6&" —*",Assumptions!$A$26:$A$32,0))&" ("&INDEX(Assumptions!$B$26:$B$32,MATCH(C6&" —*",Assumptions!$A$26:$A$32,0))&" wk)") -> R0 — Read-only pilot & foundations (8 wk)
A7: WP-04 | B7: Workspace & entity model: legal entities, brands, stores, markets, currencies, timezones, periods | C7: R0 | D7: Backend | E7: 220 | F7: =VLOOKUP(D7,Assumptions!$A$5:$B$16,2,FALSE()) -> 2400 | G7: =E7*F7 -> 528000 | H7: Backend | I7: WP-03 | J7: =IF(C7="ALL","Cross-cutting — all releases",INDEX(Assumptions!$A$26:$A$32,MATCH(C7&" —*",Assumptions!$A$26:$A$32,0))&" ("&INDEX(Assumptions!$B$26:$B$32,MATCH(C7&" —*",Assumptions!$A$26:$A$32,0))&" wk)") -> R0 — Read-only pilot & foundations (8 wk)
A8: WP-05 | B8: Amazon SP-API read connector: orders, finances, reports, settlements, inventory, inbound | C8: R0 | D8: Integration eng | E8: 480 | F8: =VLOOKUP(D8,Assumptions!$A$5:$B$16,2,FALSE()) -> 2600 | G8: =E8*F8 -> 1248000 | H8: Connector core | I8: WP-03, SP-API developer registration | J8: =IF(C8="ALL","Cross-cutting — all releases",INDEX(Assumptions!$A$26:$A$32,MATCH(C8&" —*",Assumptions!$A$26:$A$32,0))&" ("&INDEX(Assumptions!$B$26:$B$32,MATCH(C8&" —*",Assumptions!$A$26:$A$32,0))&" wk)") -> R0 — Read-only pilot & foundations (8 wk)
A9: WP-06 | B9: Raw ledger, event/revision model, idempotent ingestion, replay, reconciliation | C9: R0 | D9: Backend | E9: 320 | F9: =VLOOKUP(D9,Assumptions!$A$5:$B$16,2,FALSE()) -> 2400 | G9: =E9*F9 -> 768000 | H9: Backend | I9: WP-03, WP-05 | J9: =IF(C9="ALL","Cross-cutting — all releases",INDEX(Assumptions!$A$26:$A$32,MATCH(C9&" —*",Assumptions!$A$26:$A$32,0))&" ("&INDEX(Assumptions!$B$26:$B$32,MATCH(C9&" —*",Assumptions!$A$26:$A$32,0))&" wk)") -> R0 — Read-only pilot & foundations (8 wk)
A10: WP-07 | B10: Financial engine: fee taxonomy, COGS policies, allocations, FX, period close | C10: R1 | D10: Financial/data eng | E10: 520 | F10: =VLOOKUP(D10,Assumptions!$A$5:$B$16,2,FALSE()) -> 2600 | G10: =E10*F10 -> 1352000 | H10: Financial engine | I10: WP-06, WP-04 | J10: =IF(C10="ALL","Cross-cutting — all releases",INDEX(Assumptions!$A$26:$A$32,MATCH(C10&" —*",Assumptions!$A$26:$A$32,0))&" ("&INDEX(Assumptions!$B$26:$B$32,MATCH(C10&" —*",Assumptions!$A$26:$A$32,0))&" wk)") -> R1 — India-first unified profit core (14 wk)
A11: WP-08 | B11: Profit dashboards: tiles, chart, P&L, trends, map, comparisons, custom tiles | C11: R1 | D11: Frontend | E11: 480 | F11: =VLOOKUP(D11,Assumptions!$A$5:$B$16,2,FALSE()) -> 2200 | G11: =E11*F11 -> 1056000 | H11: Frontend | I11: WP-07, WP-02 | J11: =IF(C11="ALL","Cross-cutting — all releases",INDEX(Assumptions!$A$26:$A$32,MATCH(C11&" —*",Assumptions!$A$26:$A$32,0))&" ("&INDEX(Assumptions!$B$26:$B$32,MATCH(C11&" —*",Assumptions!$A$26:$A$32,0))&" wk)") -> R1 — India-first unified profit core (14 wk)
A12: WP-09 | B12: Products, COGS editor, landed-cost elements, imports/exports, sheets feed | C12: R1 | D12: Full-stack | E12: 360 | F12: =VLOOKUP(D12,Assumptions!$A$5:$B$16,2,FALSE()) -> 2400 | G12: =E12*F12 -> 864000 | H12: Frontend | I12: WP-07 | J12: =IF(C12="ALL","Cross-cutting — all releases",INDEX(Assumptions!$A$26:$A$32,MATCH(C12&" —*",Assumptions!$A$26:$A$32,0))&" ("&INDEX(Assumptions!$B$26:$B$32,MATCH(C12&" —*",Assumptions!$A$26:$A$32,0))&" wk)") -> R1 — India-first unified profit core (14 wk)
A13: WP-10 | B13: Expenses: indirect, variable/tag-based, recognition schedules, allocations | C13: R1 | D13: Full-stack | E13: 220 | F13: =VLOOKUP(D13,Assumptions!$A$5:$B$16,2,FALSE()) -> 2400 | G13: =E13*F13 -> 528000 | H13: Backend | I13: WP-07 | J13: =IF(C13="ALL","Cross-cutting — all releases",INDEX(Assumptions!$A$26:$A$32,MATCH(C13&" —*",Assumptions!$A$26:$A$32,0))&" ("&INDEX(Assumptions!$B$26:$B$32,MATCH(C13&" —*",Assumptions!$A$26:$A$32,0))&" wk)") -> R1 — India-first unified profit core (14 wk)
A14: WP-11 | B14: Reports & exports: grains, CSV/XLSX, scheduling, Claude-ready bundles | C14: R1 | D14: Backend | E14: 260 | F14: =VLOOKUP(D14,Assumptions!$A$5:$B$16,2,FALSE()) -> 2400 | G14: =E14*F14 -> 624000 | H14: Backend | I14: WP-07, WP-08 | J14: =IF(C14="ALL","Cross-cutting — all releases",INDEX(Assumptions!$A$26:$A$32,MATCH(C14&" —*",Assumptions!$A$26:$A$32,0))&" ("&INDEX(Assumptions!$B$26:$B$32,MATCH(C14&" —*",Assumptions!$A$26:$A$32,0))&" wk)") -> R1 — India-first unified profit core (14 wk)
A15: WP-12 | B15: Shopify connector: Admin GraphQL bulk, webhooks, Payments payouts, protected data | C15: R1 | D15: Integration eng | E15: 400 | F15: =VLOOKUP(D15,Assumptions!$A$5:$B$16,2,FALSE()) -> 2600 | G15: =E15*F15 -> 1040000 | H15: Connector core | I15: WP-06, Shopify read_all_orders approval | J15: =IF(C15="ALL","Cross-cutting — all releases",INDEX(Assumptions!$A$26:$A$32,MATCH(C15&" —*",Assumptions!$A$26:$A$32,0))&" ("&INDEX(Assumptions!$B$26:$B$32,MATCH(C15&" —*",Assumptions!$A$26:$A$32,0))&" wk)") -> R1 — India-first unified profit core (14 wk)
... A39: WP-39 | B39: Operations connectors: ShipStation, Flexport/SFN, Veeqo, CJ Dropshipping (read-only) | C39: R5 | D39: Integration eng | E39: 160 | F39: =VLOOKUP(D39,Assumptions!$A$5:$B$16,2,FALSE()) -> 2600 | G39: =E39*F39 -> 416000 | H39: Connector extended | I39: WP-06, WP-13; per-connector access | J39: =IF(C39="ALL","Cross-cutting — all releases",INDEX(Assumptions!$A$26:$A$32,MATCH(C39&" —*",Assumptions!$A$26:$A$32,0))&" ("&INDEX(Assumptions!$B$26:$B$32,MATCH(C39&" —*",Assumptions!$A$26:$A$32,0))&" wk)") -> R5 — Extended operations connectors & clients (10 wk)
A40: TOTAL | E40: =SUM(E4:E39) -> 11180 | G40: =SUM(G4:G39) -> 27604000 | I40: =IF(E40=11180,"OK — matches register 11,180 h","CHECK vs register 11,180 h") -> OK — matches register 11,180 h
A42: Category list (used by other sheets): Discovery, Design, Backend, Frontend, Financial engine, Connector core, Connector extended, Automation, QA-security, DevOps, Migration, Training, Leadership
A43: Note: 'Training' category has no WP (training is a one-time non-labour allowance on Assumptions); WP-29 covers migration + documentation labour. Categories and dependencies are planning classifications held in build_cost_model.py (not in the register).

Sheet Build_Summary
A1: Build summary — by release, initial bounded release vs full parity, by category
A2: All INR. Contingency = labour × contingency %.
A4: Release | B4: Hours | C4: Labour cost | D4: Contingency | E4: Total incl. contingency | F4: Note
A5: R0 — Read-only pilot & foundations | B5: =SUMIFS(WorkPackages!$E$4:$E$39,WorkPackages!$C$4:$C$39,"R0") -> 1840 | C5: =SUMIFS(WorkPackages!$G$4:$G$39,WorkPackages!$C$4:$C$39,"R0") -> 4844000 | D5: =C5*Assumptions!$B$19 -> 968800 | E5: =C5+D5 -> 5812800 | F5: Workspace, entities, connectors read-only, raw ledger, 90-day backfill, no operational wri
A6: R1 — India-first unified profit core | B6: =SUMIFS(WorkPackages!$E$4:$E$39,WorkPackages!$C$4:$C$39,"R1") -> 4200 | C6: =SUMIFS(WorkPackages!$G$4:$G$39,WorkPackages!$C$4:$C$39,"R1") -> 10376000 | D6: =C6*Assumptions!$B$19 -> 2075200 | E6: =C6+D6 -> 12451200 | F6: One dashboard for Amazon.in + Shopify India + manual B2B: Sellerboard-compatible P&L, COGS
A7: R2 — All markets & marketplaces | B7: =SUMIFS(WorkPackages!$E$4:$E$39,WorkPackages!$C$4:$C$39,"R2") -> 1240 | C7: =SUMIFS(WorkPackages!$G$4:$G$39,WorkPackages!$C$4:$C$39,"R2") -> 3180000 | D7: =C7*Assumptions!$B$19 -> 636000 | E7: =C7+D7 -> 3816000 | F7: UK/US/FR/DE entities and stores, every other Amazon marketplace (NA/EU/FE regions), Walmar
A8: R3 — Operations | B8: =SUMIFS(WorkPackages!$E$4:$E$39,WorkPackages!$C$4:$C$39,"R3") -> 1260 | C8: =SUMIFS(WorkPackages!$G$4:$G$39,WorkPackages!$C$4:$C$39,"R3") -> 3024000 | D8: =C8*Assumptions!$B$19 -> 604800 | E8: =C8+D8 -> 3628800 | F8: Inventory planner, POs, suppliers, FBA/WFS shipments, reimbursement candidates (Money Back
A9: R4 — Pricing automation (conditional) | B9: =SUMIFS(WorkPackages!$E$4:$E$39,WorkPackages!$C$4:$C$39,"R4") -> 300 | C9: =SUMIFS(WorkPackages!$G$4:$G$39,WorkPackages!$C$4:$C$39,"R4") -> 720000 | D9: =C9*Assumptions!$B$19 -> 144000 | E9: =C9+D9 -> 864000 | F9: Repricer contract (simulation-first; writes only after approval, maker-checker, canary, ki
A10: R5 — Extended operations connectors & clients | B10: =SUMIFS(WorkPackages!$E$4:$E$39,WorkPackages!$C$4:$C$39,"R5") -> 740 | C10: =SUMIFS(WorkPackages!$G$4:$G$39,WorkPackages!$C$4:$C$39,"R5") -> 1764000 | D10: =C10*Assumptions!$B$19 -> 352800 | E10: =C10+D10 -> 2116800 | F10: ShipStation/Flexport/SFN/Veeqo/CJ connectors, PWA extras, browser extension, QuickBooks/Ta
A11: ALL | B11: =SUMIFS(WorkPackages!$E$4:$E$39,WorkPackages!$C$4:$C$39,"ALL") -> 1600 | C11: =SUMIFS(WorkPackages!$G$4:$G$39,WorkPackages!$C$4:$C$39,"ALL") -> 3696000 | D11: =C11*Assumptions!$B$19 -> 739200 | E11: =C11+D11 -> 4435200 | F11: Cross-cutting WPs (QA, DevOps, migration, leadership)
A12: TOTAL — Full approved parity (all WPs) | B12: =SUM(B5:B11) -> 11180 | C12: =SUM(C5:C11) -> 27604000 | D12: =SUM(D5:D11) -> 5520800 | E12: =SUM(E5:E11) -> 33124800
A14: Initial bounded release (R0 + R1 + pro-rata share of ALL WPs by hours)
A15: Pro-rata factor = (hours R0 + hours R1) ÷ (hours R0..R5, excluding ALL) | B15: =IF(SUM(B5:B10)=0,0,(B5+B6)/SUM(B5:B10)) -> 0.63048017
A16: Component | B16: Hours | C16: Labour cost | D16: Contingency | E16: Total incl. contingency | F16: Formula
A17: R0 + R1 direct | B17: =B5+B6 -> 6040 | C17: =C5+C6 -> 15220000 | D17: =D5+D6 -> 3044000 | E17: =E5+E6 -> 18264000 | F17: Sum of R0 and R1 rows
A18: Pro-rata share of ALL WPs | B18: =B11*$B$15 -> 1008.7683 | C18: =C11*$B$15 -> 2330254.7 | D18: =D11*$B$15 -> 466050.94 | E18: =E11*$B$15 -> 2796305.6 | F18: ALL row × pro-rata factor
A19: INITIAL BOUNDED RELEASE — total | B19: =B17+B18 -> 7048.7683 | C19: =C17+C18 -> 17550255 | D19: =D17+D18 -> 3510050.9 | E19: =E17+E18 -> 21060306
A20: FULL APPROVED PARITY — total | B20: =B12 -> 11180 | C20: =C12 -> 27604000 | D20: =D12 -> 5520800 | E20: =E12 -> 33124800
A21: Initial as % of full | C21: =IF(C20=0,0,C19/C20) -> 0.63578665
A23: By category
A24: Category | B24: Hours | C24: Labour cost | D24: Contingency | E24: Total incl. contingency | F24: Share of labour
A25: Discovery | B25: =SUMIFS(WorkPackages!$E$4:$E$39,WorkPackages!$H$4:$H$39,"Discovery") -> 160 | C25: =SUMIFS(WorkPackages!$G$4:$G$39,WorkPackages!$H$4:$H$39,"Discovery") -> 560000 | D25: =C25*Assumptions!$B$19 -> 112000 | E25: =C25+D25 -> 672000 | F25: =IF($C$12=0,0,C25/$C$12) -> 0.020286915
A26: Design | B26: =SUMIFS(WorkPackages!$E$4:$E$39,WorkPackages!$H$4:$H$39,"Design") -> 240 | C26: =SUMIFS(WorkPackages!$G$4:$G$39,WorkPackages!$H$4:$H$39,"Design") -> 480000 | D26: =C26*Assumptions!$B$19 -> 96000 | E26: =C26+D26 -> 576000 | F26: =IF($C$12=0,0,C26/$C$12) -> 0.017388784
A27: Backend | B27: =SUMIFS(WorkPackages!$E$4:$E$39,WorkPackages!$H$4:$H$39,"Backend") -> 2700 | C27: =SUMIFS(WorkPackages!$G$4:$G$39,WorkPackages!$H$4:$H$39,"Backend") -> 6732000 | D27: =C27*Assumptions!$B$19 -> 1346400 | E27: =C27+D27 -> 8078400 | F27: =IF($C$12=0,0,C27/$C$12) -> 0.2438777
A28: Frontend | B28: =SUMIFS(WorkPackages!$E$4:$E$39,WorkPackages!$H$4:$H$39,"Frontend") -> 1260 | C28: =SUMIFS(WorkPackages!$G$4:$G$39,WorkPackages!$H$4:$H$39,"Frontend") -> 2844000 | D28: =C28*Assumptions!$B$19 -> 568800 | E28: =C28+D28 -> 3412800 | F28: =IF($C$12=0,0,C28/$C$12) -> 0.10302855
A29: Financial engine | B29: =SUMIFS(WorkPackages!$E$4:$E$39,WorkPackages!$H$4:$H$39,"Financial engine") -> 1700 | C29: =SUMIFS(WorkPackages!$G$4:$G$39,WorkPackages!$H$4:$H$39,"Financial engine") -> 4376000 | D29: =C29*Assumptions!$B$19 -> 875200 | E29: =C29+D29 -> 5251200 | F29: =IF($C$12=0,0,C29/$C$12) -> 0.15852775
A30: Connector core | B30: =SUMIFS(WorkPackages!$E$4:$E$39,WorkPackages!$H$4:$H$39,"Connector core") -> 1580 | C30: =SUMIFS(WorkPackages!$G$4:$G$39,WorkPackages!$H$4:$H$39,"Connector core") -> 4108000 | D30: =C30*Assumptions!$B$19 -> 821600 | E30: =C30+D30 -> 4929600 | F30: =IF($C$12=0,0,C30/$C$12) -> 0.14881901
A31: Connector extended | B31: =SUMIFS(WorkPackages!$E$4:$E$39,WorkPackages!$H$4:$H$39,"Connector extended") -> 1120 | C31: =SUMIFS(WorkPackages!$G$4:$G$39,WorkPackages!$H$4:$H$39,"Connector extended") -> 2840000 | D31: =C31*Assumptions!$B$19 -> 568000 | E31: =C31+D31 -> 3408000 | F31: =IF($C$12=0,0,C31/$C$12) -> 0.10288364
A32: Automation | B32: =SUMIFS(WorkPackages!$E$4:$E$39,WorkPackages!$H$4:$H$39,"Automation") -> 820 | C32: =SUMIFS(WorkPackages!$G$4:$G$39,WorkPackages!$H$4:$H$39,"Automation") -> 1968000 | D32: =C32*Assumptions!$B$19 -> 393600 | E32: =C32+D32 -> 2361600 | F32: =IF($C$12=0,0,C32/$C$12) -> 0.071294015
A33: QA-security | B33: =SUMIFS(WorkPackages!$E$4:$E$39,WorkPackages!$H$4:$H$39,"QA-security") -> 640 | C33: =SUMIFS(WorkPackages!$G$4:$G$39,WorkPackages!$H$4:$H$39,"QA-security") -> 1152000 | D33: =C33*Assumptions!$B$19 -> 230400 | E33: =C33+D33 -> 1382400 | F33: =IF($C$12=0,0,C33/$C$12) -> 0.041733082
A34: DevOps | B34: =SUMIFS(WorkPackages!$E$4:$E$39,WorkPackages!$H$4:$H$39,"DevOps") -> 320 | C34: =SUMIFS(WorkPackages!$G$4:$G$39,WorkPackages!$H$4:$H$39,"DevOps") -> 768000 | D34: =C34*Assumptions!$B$19 -> 153600 | E34: =C34+D34 -> 921600 | F34: =IF($C$12=0,0,C34/$C$12) -> 0.027822055
A35: Migration | B35: =SUMIFS(WorkPackages!$E$4:$E$39,WorkPackages!$H$4:$H$39,"Migration") -> 240 | C35: =SUMIFS(WorkPackages!$G$4:$G$39,WorkPackages!$H$4:$H$39,"Migration") -> 576000 | D35: =C35*Assumptions!$B$19 -> 115200 | E35: =C35+D35 -> 691200 | F35: =IF($C$12=0,0,C35/$C$12) -> 0.020866541
A36: Training | B36: =SUMIFS(WorkPackages!$E$4:$E$39,WorkPackages!$H$4:$H$39,"Training") -> 0 | C36: =SUMIFS(WorkPackages!$G$4:$G$39,WorkPackages!$H$4:$H$39,"Training") -> 0 | D36: =C36*Assumptions!$B$19 -> 0 | E36: =C36+D36 -> 0 | F36: =IF($C$12=0,0,C36/$C$12) -> 0
A37: Leadership | B37: =SUMIFS(WorkPackages!$E$4:$E$39,WorkPackages!$H$4:$H$39,"Leadership") -> 400 | C37: =SUMIFS(WorkPackages!$G$4:$G$39,WorkPackages!$H$4:$H$39,"Leadership") -> 1200000 | D37: =C37*Assumptions!$B$19 -> 240000 | E37: =C37+D37 -> 1440000 | F37: =IF($C$12=0,0,C37/$C$12) -> 0.043471961
A38: TOTAL (check = full parity) | B38: =SUM(B25:B37) -> 11180 | C38: =SUM(C25:C37) -> 27604000 | D38: =SUM(D25:D37) -> 5520800 | E38: =SUM(E25:E37) -> 33124800 | F38: =IF(ABS(C38-C12)<1,"OK — reconciles","CHECK") -> OK — reconciles

Sheet Capacity_Schedule
A1: Capacity schedule — FTE by role per release = hours ÷ (nominal h/mo × productive factor) ÷ months in release
A2: Months = calendar weeks × 12/52 (weeks from scope_register.json via Assumptions). FTE > 1.0 flagged (needs more than one person of that role, or a longer calendar).
A4: Productive hours per FTE-month | B4: =Assumptions!$B$20*Assumptions!$B$21 -> 120
A6: Role | B6: R0 | C6: R1 | D6: R2 | E6: R3 | F6: R4 | G6: R5 | H6: ALL | I6: Flag | J6: R0 flag | K6: R1 flag | L6: R2 flag | M6: R3 flag | N6: R4 flag | O6: R5 flag | P6: ALL flag
A7: Calendar weeks | B7: =Assumptions!$B$26 -> 8 | C7: =Assumptions!$B$27 -> 14 | D7: =Assumptions!$B$28 -> 14 | E7: =Assumptions!$B$29 -> 10 | F7: =Assumptions!$B$30 -> 6 | G7: =Assumptions!$B$31 -> 10 | H7: =Assumptions!$B$32 -> 62
A8: Months | B8: =B7*12/52 -> 1.8461538 | C8: =C7*12/52 -> 3.2307692 | D8: =D7*12/52 -> 3.2307692 | E8: =E7*12/52 -> 2.3076923 | F8: =F7*12/52 -> 1.3846154 | G8: =G7*12/52 -> 2.3076923 | H8: =H7*12/52 -> 14.307692
A9: Solution architect | B9: =IF(B$8=0,0,SUMIFS(WorkPackages!$E$4:$E$39,WorkPackages!$D$4:$D$39,$A9,WorkPackages!$C$4:$C$39,"R0")/$B$4/B$8) -> 0.72222222 | C9: =IF(C$8=0,0,SUMIFS(WorkPackages!$E$4:$E$39,WorkPackages!$D$4:$D$39,$A9,WorkPackages!$C$4:$C$39,"R1")/$B$4/C$8) -> 0 | D9: =IF(D$8=0,0,SUMIFS(WorkPackages!$E$4:$E$39,WorkPackages!$D$4:$D$39,$A9,WorkPackages!$C$4:$C$39,"R2")/$B$4/D$8) -> 0 | E9: =IF(E$8=0,0,SUMIFS(WorkPackages!$E$4:$E$39,WorkPackages!$D$4:$D$39,$A9,WorkPackages!$C$4:$C$39,"R3")/$B$4/E$8) -> 0 | F9: =IF(F$8=0,0,SUMIFS(WorkPackages!$E$4:$E$39,WorkPackages!$D$4:$D$39,$A9,WorkPackages!$C$4:$C$39,"R4")/$B$4/F$8) -> 0 | G9: =IF(G$8=0,0,SUMIFS(WorkPackages!$E$4:$E$39,WorkPackages!$D$4:$D$39,$A9,WorkPackages!$C$4:$C$39,"R5")/$B$4/G$8) -> 0 | H9: =IF(H$8=0,0,SUMIFS(WorkPackages!$E$4:$E$39,WorkPackages!$D$4:$D$39,$A9,WorkPackages!$C$4:$C$39,"ALL")/$B$4/H$8) -> 0 | J9: =IF(B9>1,">1 FTE","") | K9: =IF(C9>1,">1 FTE","") | L9: =IF(D9>1,">1 FTE","") | M9: =IF(E9>1,">1 FTE","") | N9: =IF(F9>1,">1 FTE","") | O9: =IF(G9>1,">1 FTE","") | P9: =IF(H9>1,">1 FTE","")
A10: Backend lead | B10: =IF(B$8=0,0,SUMIFS(WorkPackages!$E$4:$E$39,WorkPackages!$D$4:$D$39,$A10,WorkPackages!$C$4:$C$39,"R0")/$B$4/B$8) -> 1.8958333 | C10: =IF(C$8=0,0,SUMIFS(WorkPackages!$E$4:$E$39,WorkPackages!$D$4:$D$39,$A10,WorkPackages!$C$4:$C$39,"R1")/$B$4/C$8) -> 0 | D10: =IF(D$8=0,0,SUMIFS(WorkPackages!$E$4:$E$39,WorkPackages!$D$4:$D$39,$A10,WorkPackages!$C$4:$C$39,"R2")/$B$4/D$8) -> 0 | E10: =IF(E$8=0,0,SUMIFS(WorkPackages!$E$4:$E$39,WorkPackages!$D$4:$D$39,$A10,WorkPackages!$C$4:$C$39,"R3")/$B$4/E$8) -> 0 | F10: =IF(F$8=0,0,SUMIFS(WorkPackages!$E$4:$E$39,WorkPackages!$D$4:$D$39,$A10,WorkPackages!$C$4:$C$39,"R4")/$B$4/F$8) -> 0 | G10: =IF(G$8=0,0,SUMIFS(WorkPackages!$E$4:$E$39,WorkPackages!$D$4:$D$39,$A10,WorkPackages!$C$4:$C$39,"R5")/$B$4/G$8) -> 0 | H10: =IF(H$8=0,0,SUMIFS(WorkPackages!$E$4:$E$39,WorkPackages!$D$4:$D$39,$A10,WorkPackages!$C$4:$C$39,"ALL")/$B$4/H$8) -> 0 | J10: =IF(B10>1,">1 FTE","") -> >1 FTE | K10: =IF(C10>1,">1 FTE","") | L10: =IF(D10>1,">1 FTE","") | M10: =IF(E10>1,">1 FTE","") | N10: =IF(F10>1,">1 FTE","") | O10: =IF(G10>1,">1 FTE","") | P10: =IF(H10>1,">1 FTE","")
A11: Backend | B11: =IF(B$8=0,0,SUMIFS(WorkPackages!$E$4:$E$39,WorkPackages!$D$4:$D$39,$A11,WorkPackages!$C$4:$C$39,"R0")/$B$4/B$8) -> 2.4375 | C11: =IF(C$8=0,0,SUMIFS(WorkPackages!$E$4:$E$39,WorkPackages!$D$4:$D$39,$A11,WorkPackages!$C$4:$C$39,"R1")/$B$4/C$8) -> 0.67063492 | D11: =IF(D$8=0,0,SUMIFS(WorkPackages!$E$4:$E$39,WorkPackages!$D$4:$D$39,$A11,WorkPackages!$C$4:$C$39,"R2")/$B$4/D$8) -> 0 | E11: =IF(E$8=0,0,SUMIFS(WorkPackages!$E$4:$E$39,WorkPackages!$D$4:$D$39,$A11,WorkPackages!$C$4:$C$39,"R3")/$B$4/E$8) -> 1.8777778 | F11: =IF(F$8=0,0,SUMIFS(WorkPackages!$E$4:$E$39,WorkPackages!$D$4:$D$39,$A11,WorkPackages!$C$4:$C$39,"R4")/$B$4/F$8) -> 0 | G11: =IF(G$8=0,0,SUMIFS(WorkPackages!$E$4:$E$39,WorkPackages!$D$4:$D$39,$A11,WorkPackages!$C$4:$C$39,"R5")/$B$4/G$8) -> 0.57777778 | H11: =IF(H$8=0,0,SUMIFS(WorkPackages!$E$4:$E$39,WorkPackages!$D$4:$D$39,$A11,WorkPackages!$C$4:$C$39,"ALL")/$B$4/H$8) -> 0 | J11: =IF(B11>1,">1 FTE","") -> >1 FTE | K11: =IF(C11>1,">1 FTE","") | L11: =IF(D11>1,">1 FTE","") | M11: =IF(E11>1,">1 FTE","") -> >1 FTE | N11: =IF(F11>1,">1 FTE","") | O11: =IF(G11>1,">1 FTE","") | P11: =IF(H11>1,">1 FTE","")
A12: Frontend | B12: =IF(B$8=0,0,SUMIFS(WorkPackages!$E$4:$E$39,WorkPackages!$D$4:$D$39,$A12,WorkPackages!$C$4:$C$39,"R0")/$B$4/B$8) -> 0 | C12: =IF(C$8=0,0,SUMIFS(WorkPackages!$E$4:$E$39,WorkPackages!$D$4:$D$39,$A12,WorkPackages!$C$4:$C$39,"R1")/$B$4/C$8) -> 1.7539683 | D12: =IF(D$8=0,0,SUMIFS(WorkPackages!$E$4:$E$39,WorkPackages!$D$4:$D$39,$A12,WorkPackages!$C$4:$C$39,"R2")/$B$4/D$8) -> 0 | E12: =IF(E$8=0,0,SUMIFS(WorkPackages!$E$4:$E$39,WorkPackages!$D$4:$D$39,$A12,WorkPackages!$C$4:$C$39,"R3")/$B$4/E$8) -> 0 | F12: =IF(F$8=0,0,SUMIFS(WorkPackages!$E$4:$E$39,WorkPackages!$D$4:$D$39,$A12,WorkPackages!$C$4:$C$39,"R4")/$B$4/F$8) -> 0 | G12: =IF(G$8=0,0,SUMIFS(WorkPackages!$E$4:$E$39,WorkPackages!$D$4:$D$39,$A12,WorkPackages!$C$4:$C$39,"R5")/$B$4/G$8) -> 0.79444444 | H12: =IF(H$8=0,0,SUMIFS(WorkPackages!$E$4:$E$39,WorkPackages!$D$4:$D$39,$A12,WorkPackages!$C$4:$C$39,"ALL")/$B$4/H$8) -> 0 | J12: =IF(B12>1,">1 FTE","") | K12: =IF(C12>1,">1 FTE","") -> >1 FTE | L12: =IF(D12>1,">1 FTE","") | M12: =IF(E12>1,">1 FTE","") | N12: =IF(F12>1,">1 FTE","") | O12: =IF(G12>1,">1 FTE","") | P12: =IF(H12>1,">1 FTE","")
A13: Full-stack | B13: =IF(B$8=0,0,SUMIFS(WorkPackages!$E$4:$E$39,WorkPackages!$D$4:$D$39,$A13,WorkPackages!$C$4:$C$39,"R0")/$B$4/B$8) -> 0 | C13: =IF(C$8=0,0,SUMIFS(WorkPackages!$E$4:$E$39,WorkPackages!$D$4:$D$39,$A13,WorkPackages!$C$4:$C$39,"R1")/$B$4/C$8) -> 2.8373016 | D13: =IF(D$8=0,0,SUMIFS(WorkPackages!$E$4:$E$39,WorkPackages!$D$4:$D$39,$A13,WorkPackages!$C$4:$C$39,"R2")/$B$4/D$8) -> 0 | E13: =IF(E$8=0,0,SUMIFS(WorkPackages!$E$4:$E$39,WorkPackages!$D$4:$D$39,$A13,WorkPackages!$C$4:$C$39,"R3")/$B$4/E$8) -> 2.6722222 | F13: =IF(F$8=0,0,SUMIFS(WorkPackages!$E$4:$E$39,WorkPackages!$D$4:$D$39,$A13,WorkPackages!$C$4:$C$39,"R4")/$B$4/F$8) -> 1.8055556 | G13: =IF(G$8=0,0,SUMIFS(WorkPackages!$E$4:$E$39,WorkPackages!$D$4:$D$39,$A13,WorkPackages!$C$4:$C$39,"R5")/$B$4/G$8) -> 0.72222222 | H13: =IF(H$8=0,0,SUMIFS(WorkPackages!$E$4:$E$39,WorkPackages!$D$4:$D$39,$A13,WorkPackages!$C$4:$C$39,"ALL")/$B$4/H$8) -> 0 | J13: =IF(B13>1,">1 FTE","") | K13: =IF(C13>1,">1 FTE","") -> >1 FTE | L13: =IF(D13>1,">1 FTE","") | M13: =IF(E13>1,">1 FTE","") -> >1 FTE | N13: =IF(F13>1,">1 FTE","") -> >1 FTE | O13: =IF(G13>1,">1 FTE","") | P13: =IF(H13>1,">1 FTE","")
A14: Integration eng | B14: =IF(B$8=0,0,SUMIFS(WorkPackages!$E$4:$E$39,WorkPackages!$D$4:$D$39,$A14,WorkPackages!$C$4:$C$39,"R0")/$B$4/B$8) -> 2.1666667 | C14: =IF(C$8=0,0,SUMIFS(WorkPackages!$E$4:$E$39,WorkPackages!$D$4:$D$39,$A14,WorkPackages!$C$4:$C$39,"R1")/$B$4/C$8) -> 2.218254 | D14: =IF(D$8=0,0,SUMIFS(WorkPackages!$E$4:$E$39,WorkPackages!$D$4:$D$39,$A14,WorkPackages!$C$4:$C$39,"R2")/$B$4/D$8) -> 2.1666667 | E14: =IF(E$8=0,0,SUMIFS(WorkPackages!$E$4:$E$39,WorkPackages!$D$4:$D$39,$A14,WorkPackages!$C$4:$C$39,"R3")/$B$4/E$8) -> 0 | F14: =IF(F$8=0,0,SUMIFS(WorkPackages!$E$4:$E$39,WorkPackages!$D$4:$D$39,$A14,WorkPackages!$C$4:$C$39,"R4")/$B$4/F$8) -> 0 | G14: =IF(G$8=0,0,SUMIFS(WorkPackages!$E$4:$E$39,WorkPackages!$D$4:$D$39,$A14,WorkPackages!$C$4:$C$39,"R5")/$B$4/G$8) -> 0.57777778 | H14: =IF(H$8=0,0,SUMIFS(WorkPackages!$E$4:$E$39,WorkPackages!$D$4:$D$39,$A14,WorkPackages!$C$4:$C$39,"ALL")/$B$4/H$8) -> 0 | J14: =IF(B14>1,">1 FTE","") -> >1 FTE | K14: =IF(C14>1,">1 FTE","") -> >1 FTE | L14: =IF(D14>1,">1 FTE","") -> >1 FTE | M14: =IF(E14>1,">1 FTE","") | N14: =IF(F14>1,">1 FTE","") | O14: =IF(G14>1,">1 FTE","") | P14: =IF(H14>1,">1 FTE","")
A15: Financial/data eng | B15: =IF(B$8=0,0,SUMIFS(WorkPackages!$E$4:$E$39,WorkPackages!$D$4:$D$39,$A15,WorkPackages!$C$4:$C$39,"R0")/$B$4/B$8) -> 0 | C15: =IF(C$8=0,0,SUMIFS(WorkPackages!$E$4:$E$39,WorkPackages!$D$4:$D$39,$A15,WorkPackages!$C$4:$C$39,"R1")/$B$4/C$8) -> 3.3531746 | D15: =IF(D$8=0,0,SUMIFS(WorkPackages!$E$4:$E$39,WorkPackages!$D$4:$D$39,$A15,WorkPackages!$C$4:$C$39,"R2")/$B$4/D$8) -> 0.46428571 | E15: =IF(E$8=0,0,SUMIFS(WorkPackages!$E$4:$E$39,WorkPackages!$D$4:$D$39,$A15,WorkPackages!$C$4:$C$39,"R3")/$B$4/E$8) -> 0 | F15: =IF(F$8=0,0,SUMIFS(WorkPackages!$E$4:$E$39,WorkPackages!$D$4:$D$39,$A15,WorkPackages!$C$4:$C$39,"R4")/$B$4/F$8) -> 0 | G15: =IF(G$8=0,0,SUMIFS(WorkPackages!$E$4:$E$39,WorkPackages!$D$4:$D$39,$A15,WorkPackages!$C$4:$C$39,"R5")/$B$4/G$8) -> 0 | H15: =IF(H$8=0,0,SUMIFS(WorkPackages!$E$4:$E$39,WorkPackages!$D$4:$D$39,$A15,WorkPackages!$C$4:$C$39,"ALL")/$B$4/H$8) -> 0 | J15: =IF(B15>1,">1 FTE","") | K15: =IF(C15>1,">1 FTE","") -> >1 FTE | L15: =IF(D15>1,">1 FTE","") | M15: =IF(E15>1,">1 FTE","") | N15: =IF(F15>1,">1 FTE","") | O15: =IF(G15>1,">1 FTE","") | P15: =IF(H15>1,">1 FTE","")
A16: Data eng | B16: =IF(B$8=0,0,SUMIFS(WorkPackages!$E$4:$E$39,WorkPackages!$D$4:$D$39,$A16,WorkPackages!$C$4:$C$39,"R0")/$B$4/B$8) -> 0 | C16: =IF(C$8=0,0,SUMIFS(WorkPackages!$E$4:$E$39,WorkPackages!$D$4:$D$39,$A16,WorkPackages!$C$4:$C$39,"R1")/$B$4/C$8) -> 0 | D16: =IF(D$8=0,0,SUMIFS(WorkPackages!$E$4:$E$39,WorkPackages!$D$4:$D$39,$A16,WorkPackages!$C$4:$C$39,"R2")/$B$4/D$8) -> 0.56746032 | E16: =IF(E$8=0,0,SUMIFS(WorkPackages!$E$4:$E$39,WorkPackages!$D$4:$D$39,$A16,WorkPackages!$C$4:$C$39,"R3")/$B$4/E$8) -> 0 | F16: =IF(F$8=0,0,SUMIFS(WorkPackages!$E$4:$E$39,WorkPackages!$D$4:$D$39,$A16,WorkPackages!$C$4:$C$39,"R4")/$B$4/F$8) -> 0 | G16: =IF(G$8=0,0,SUMIFS(WorkPackages!$E$4:$E$39,WorkPackages!$D$4:$D$39,$A16,WorkPackages!$C$4:$C$39,"R5")/$B$4/G$8) -> 0 | H16: =IF(H$8=0,0,SUMIFS(WorkPackages!$E$4:$E$39,WorkPackages!$D$4:$D$39,$A16,WorkPackages!$C$4:$C$39,"ALL")/$B$4/H$8) -> 0.13978495 | J16: =IF(B16>1,">1 FTE","") | K16: =IF(C16>1,">1 FTE","") | L16: =IF(D16>1,">1 FTE","") | M16: =IF(E16>1,">1 FTE","") | N16: =IF(F16>1,">1 FTE","") | O16: =IF(G16>1,">1 FTE","") | P16: =IF(H16>1,">1 FTE","")
A17: Product designer | B17: =IF(B$8=0,0,SUMIFS(WorkPackages!$E$4:$E$39,WorkPackages!$D$4:$D$39,$A17,WorkPackages!$C$4:$C$39,"R0")/$B$4/B$8) -> 1.0833333 | C17: =IF(C$8=0,0,SUMIFS(WorkPackages!$E$4:$E$39,WorkPackages!$D$4:$D$39,$A17,WorkPackages!$C$4:$C$39,"R1")/$B$4/C$8) -> 0 | D17: =IF(D$8=0,0,SUMIFS(WorkPackages!$E$4:$E$39,WorkPackages!$D$4:$D$39,$A17,WorkPackages!$C$4:$C$39,"R2")/$B$4/D$8) -> 0 | E17: =IF(E$8=0,0,SUMIFS(WorkPackages!$E$4:$E$39,WorkPackages!$D$4:$D$39,$A17,WorkPackages!$C$4:$C$39,"R3")/$B$4/E$8) -> 0 | F17: =IF(F$8=0,0,SUMIFS(WorkPackages!$E$4:$E$39,WorkPackages!$D$4:$D$39,$A17,WorkPackages!$C$4:$C$39,"R4")/$B$4/F$8) -> 0 | G17: =IF(G$8=0,0,SUMIFS(WorkPackages!$E$4:$E$39,WorkPackages!$D$4:$D$39,$A17,WorkPackages!$C$4:$C$39,"R5")/$B$4/G$8) -> 0 | H17: =IF(H$8=0,0,SUMIFS(WorkPackages!$E$4:$E$39,WorkPackages!$D$4:$D$39,$A17,WorkPackages!$C$4:$C$39,"ALL")/$B$4/H$8) -> 0 | J17: =IF(B17>1,">1 FTE","") -> >1 FTE | K17: =IF(C17>1,">1 FTE","") | L17: =IF(D17>1,">1 FTE","") | M17: =IF(E17>1,">1 FTE","") | N17: =IF(F17>1,">1 FTE","") | O17: =IF(G17>1,">1 FTE","") | P17: =IF(H17>1,">1 FTE","")
A18: QA/security | B18: =IF(B$8=0,0,SUMIFS(WorkPackages!$E$4:$E$39,WorkPackages!$D$4:$D$39,$A18,WorkPackages!$C$4:$C$39,"R0")/$B$4/B$8) -> 0 | C18: =IF(C$8=0,0,SUMIFS(WorkPackages!$E$4:$E$39,WorkPackages!$D$4:$D$39,$A18,WorkPackages!$C$4:$C$39,"R1")/$B$4/C$8) -> 0 | D18: =IF(D$8=0,0,SUMIFS(WorkPackages!$E$4:$E$39,WorkPackages!$D$4:$D$39,$A18,WorkPackages!$C$4:$C$39,"R2")/$B$4/D$8) -> 0 | E18: =IF(E$8=0,0,SUMIFS(WorkPackages!$E$4:$E$39,WorkPackages!$D$4:$D$39,$A18,WorkPackages!$C$4:$C$39,"R3")/$B$4/E$8) -> 0 | F18: =IF(F$8=0,0,SUMIFS(WorkPackages!$E$4:$E$39,WorkPackages!$D$4:$D$39,$A18,WorkPackages!$C$4:$C$39,"R4")/$B$4/F$8) -> 0 | G18: =IF(G$8=0,0,SUMIFS(WorkPackages!$E$4:$E$39,WorkPackages!$D$4:$D$39,$A18,WorkPackages!$C$4:$C$39,"R5")/$B$4/G$8) -> 0 | H18: =IF(H$8=0,0,SUMIFS(WorkPackages!$E$4:$E$39,WorkPackages!$D$4:$D$39,$A18,WorkPackages!$C$4:$C$39,"ALL")/$B$4/H$8) -> 0.37275986 | J18: =IF(B18>1,">1 FTE","") | K18: =IF(C18>1,">1 FTE","") | L18: =IF(D18>1,">1 FTE","") | M18: =IF(E18>1,">1 FTE","") | N18: =IF(F18>1,">1 FTE","") | O18: =IF(G18>1,">1 FTE","") | P18: =IF(H18>1,">1 FTE","")
A19: DevOps | B19: =IF(B$8=0,0,SUMIFS(WorkPackages!$E$4:$E$39,WorkPackages!$D$4:$D$39,$A19,WorkPackages!$C$4:$C$39,"R0")/$B$4/B$8) -> 0 | C19: =IF(C$8=0,0,SUMIFS(WorkPackages!$E$4:$E$39,WorkPackages!$D$4:$D$39,$A19,WorkPackages!$C$4:$C$39,"R1")/$B$4/C$8) -> 0 | D19: =IF(D$8=0,0,SUMIFS(WorkPackages!$E$4:$E$39,WorkPackages!$D$4:$D$39,$A19,WorkPackages!$C$4:$C$39,"R2")/$B$4/D$8) -> 0 | E19: =IF(E$8=0,0,SUMIFS(WorkPackages!$E$4:$E$39,WorkPackages!$D$4:$D$39,$A19,WorkPackages!$C$4:$C$39,"R3")/$B$4/E$8) -> 0 | F19: =IF(F$8=0,0,SUMIFS(WorkPackages!$E$4:$E$39,WorkPackages!$D$4:$D$39,$A19,WorkPackages!$C$4:$C$39,"R4")/$B$4/F$8) -> 0 | G19: =IF(G$8=0,0,SUMIFS(WorkPackages!$E$4:$E$39,WorkPackages!$D$4:$D$39,$A19,WorkPackages!$C$4:$C$39,"R5")/$B$4/G$8) -> 0 | H19: =IF(H$8=0,0,SUMIFS(WorkPackages!$E$4:$E$39,WorkPackages!$D$4:$D$39,$A19,WorkPackages!$C$4:$C$39,"ALL")/$B$4/H$8) -> 0.18637993 | J19: =IF(B19>1,">1 FTE","") | K19: =IF(C19>1,">1 FTE","") | L19: =IF(D19>1,">1 FTE","") | M19: =IF(E19>1,">1 FTE","") | N19: =IF(F19>1,">1 FTE","") | O19: =IF(G19>1,">1 FTE","") | P19: =IF(H19>1,">1 FTE","")
A20: Delivery lead | B20: =IF(B$8=0,0,SUMIFS(WorkPackages!$E$4:$E$39,WorkPackages!$D$4:$D$39,$A20,WorkPackages!$C$4:$C$39,"R0")/$B$4/B$8) -> 0 | C20: =IF(C$8=0,0,SUMIFS(WorkPackages!$E$4:$E$39,WorkPackages!$D$4:$D$39,$A20,WorkPackages!$C$4:$C$39,"R1")/$B$4/C$8) -> 0 | D20: =IF(D$8=0,0,SUMIFS(WorkPackages!$E$4:$E$39,WorkPackages!$D$4:$D$39,$A20,WorkPackages!$C$4:$C$39,"R2")/$B$4/D$8) -> 0 | E20: =IF(E$8=0,0,SUMIFS(WorkPackages!$E$4:$E$39,WorkPackages!$D$4:$D$39,$A20,WorkPackages!$C$4:$C$39,"R3")/$B$4/E$8) -> 0 | F20: =IF(F$8=0,0,SUMIFS(WorkPackages!$E$4:$E$39,WorkPackages!$D$4:$D$39,$A20,WorkPackages!$C$4:$C$39,"R4")/$B$4/F$8) -> 0 | G20: =IF(G$8=0,0,SUMIFS(WorkPackages!$E$4:$E$39,WorkPackages!$D$4:$D$39,$A20,WorkPackages!$C$4:$C$39,"R5")/$B$4/G$8) -> 0 | H20: =IF(H$8=0,0,SUMIFS(WorkPackages!$E$4:$E$39,WorkPackages!$D$4:$D$39,$A20,WorkPackages!$C$4:$C$39,"ALL")/$B$4/H$8) -> 0.23297491 | J20: =IF(B20>1,">1 FTE","") | K20: =IF(C20>1,">1 FTE","") | L20: =IF(D20>1,">1 FTE","") | M20: =IF(E20>1,">1 FTE","") | N20: =IF(F20>1,">1 FTE","") | O20: =IF(G20>1,">1 FTE","") | P20: =IF(H20>1,">1 FTE","")
A21: Total FTE (role-sum) | B21: =SUM(B9:B20) -> 8.3055556 | C21: =SUM(C9:C20) -> 10.833333 | D21: =SUM(D9:D20) -> 3.1984127 | E21: =SUM(E9:E20) -> 4.55 | F21: =SUM(F9:F20) -> 1.8055556 | G21: =SUM(G9:G20) -> 2.6722222 | H21: =SUM(H9:H20) -> 0.93189964
A23: Reading: a value of 1.4 for 'Integration eng' in R1 means the R1 calendar needs 1.4 integration engineers at 120 productive h/month, or the release stretches. ALL column spreads cross-cutting WPs across the full programme (sum of release weeks). v0.3: R1 is 14 weeks and carries WP-07..13, WP-31..35 and WP-37; R2 (14 weeks) carries WP-14, WP-23, WP-36, WP-38.

Sheet OpEx_Monthly
A1: Monthly operating cost — line items from Assumptions; low / base / high = scenario multipliers
A2: INR. Annual = monthly × 12.
A4: Line item | B4: Applies from release | C4: Monthly (base) | D4: Monthly low | E4: Monthly high | F4: Annual base | G4: Annual low | H4: Annual high | I4: Source
A5: Cloud — compute | B5: R0 | C5: =Assumptions!$B$35 -> 45000 | D5: =C5*Assumptions!$B$90 -> 36000 | E5: =C5*Assumptions!$B$92 -> 58500 | F5: =C5*12 -> 540000 | G5: =D5*12 -> 432000 | H5: =E5*12 -> 702000 | I5: Assumptions sheet
A6: Cloud — managed Postgres | B6: R0 | C6: =Assumptions!$B$36 -> 25000 | D6: =C6*Assumptions!$B$90 -> 20000 | E6: =C6*Assumptions!$B$92 -> 32500 | F6: =C6*12 -> 300000 | G6: =D6*12 -> 240000 | H6: =E6*12 -> 390000 | I6: Assumptions sheet
A7: Cloud — object storage | B7: R0 | C7: =Assumptions!$B$37 -> 8000 | D7: =C7*Assumptions!$B$90 -> 6400 | E7: =C7*Assumptions!$B$92 -> 10400 | F7: =C7*12 -> 96000 | G7: =D7*12 -> 76800 | H7: =E7*12 -> 124800 | I7: Assumptions sheet
A8: Cloud — jobs / queue | B8: R0 | C8: =Assumptions!$B$38 -> 10000 | D8: =C8*Assumptions!$B$90 -> 8000 | E8: =C8*Assumptions!$B$92 -> 13000 | F8: =C8*12 -> 120000 | G8: =D8*12 -> 96000 | H8: =E8*12 -> 156000 | I8: Assumptions sheet
A9: Cloud — egress | B9: R0 | C9: =Assumptions!$B$39 -> 5000 | D9: =C9*Assumptions!$B$90 -> 4000 | E9: =C9*Assumptions!$B$92 -> 6500 | F9: =C9*12 -> 60000 | G9: =D9*12 -> 48000 | H9: =E9*12 -> 78000 | I9: Assumptions sheet
A10: Cloud — observability | B10: R0 | C10: =Assumptions!$B$40 -> 12000 | D10: =C10*Assumptions!$B$90 -> 9600 | E10: =C10*Assumptions!$B$92 -> 15600 | F10: =C10*12 -> 144000 | G10: =D10*12 -> 115200 | H10: =E10*12 -> 187200 | I10: Assumptions sheet
A11: Cloud — backups / DR | B11: R0 | C11: =Assumptions!$B$41 -> 6000 | D11: =C11*Assumptions!$B$90 -> 4800 | E11: =C11*Assumptions!$B$92 -> 7800 | F11: =C11*12 -> 72000 | G11: =D11*12 -> 57600 | H11: =E11*12 -> 93600 | I11: Assumptions sheet
A12: Cloud — security / landing zone | B12: R0 | C12: =Assumptions!$B$42 -> 18000 | D12: =C12*Assumptions!$B$90 -> 14400 | E12: =C12*Assumptions!$B$92 -> 23400 | F12: =C12*12 -> 216000 | G12: =D12*12 -> 172800 | H12: =E12*12 -> 280800 | I12: Assumptions sheet — NEW v0.2 (handoff review C-28)
A13: Support / maintenance staff | B13: R1 | C13: =Assumptions!$B$48 -> 192000 | D13: =C13*Assumptions!$B$90 -> 153600 | E13: =C13*Assumptions!$B$92 -> 249600 | F13: =C13*12 -> 2304000 | G13: =D13*12 -> 1843200 | H13: =E13*12 -> 2995200 | I13: Assumptions sheet
A14: Provider / API upgrade allowance | B14: R0 | C14: =Assumptions!$B$49 -> 20000 | D14: =C14*Assumptions!$B$90 -> 16000 | E14: =C14*Assumptions!$B$92 -> 26000 | F14: =C14*12 -> 240000 | G14: =D14*12 -> 192000 | H14: =E14*12 -> 312000 | I14: Assumptions sheet
A15: Security review (annual ÷ 12) | B15: R0 | C15: =Assumptions!$B$50/12 -> 25000 | D15: =C15*Assumptions!$B$90 -> 20000 | E15: =C15*Assumptions!$B$92 -> 32500 | F15: =C15*12 -> 300000 | G15: =D15*12 -> 240000 | H15: =E15*12 -> 390000 | I15: Assumptions sheet
A16: Software / API — SP-API | B16: R0 | C16: =Assumptions!$B$55 -> 0 | D16: =C16*Assumptions!$B$90 -> 0 | E16: =C16*Assumptions!$B$92 -> 0 | F16: =C16*12 -> 0 | G16: =D16*12 -> 0 | H16: =E16*12 -> 0 | I16: Assumptions sheet
A17: Software / API — Ads API (spend read) | B17: R1 | C17: =Assumptions!$B$56 -> 0 | D17: =C17*Assumptions!$B$90 -> 0 | E17: =C17*Assumptions!$B$92 -> 0 | F17: =C17*12 -> 0 | G17: =D17*12 -> 0 | H17: =E17*12 -> 0 | I17: Assumptions sheet — v0.3: spend read from R1 (WP-37); no PPC analytics
A18: Software / API — Shopify custom app | B18: R1 | C18: =Assumptions!$B$57 -> 0 | D18: =C18*Assumptions!$B$90 -> 0 | E18: =C18*Assumptions!$B$92 -> 0 | F18: =C18*12 -> 0 | G18: =D18*12 -> 0 | H18: =E18*12 -> 0 | I18: Assumptions sheet — v0.2: R1 (WP-12 moved R2→R1)
A19: Software / API — other tools | B19: R0 | C19: =Assumptions!$B$58 -> 15000 | D19: =C19*Assumptions!$B$90 -> 12000 | E19: =C19*Assumptions!$B$92 -> 19500 | F19: =C19*12 -> 180000 | G19: =D19*12 -> 144000 | H19: =E19*12 -> 234000 | I19: Assumptions sheet
A20: Software / API — ChatGPT/Codex seats (build tool) | B20: R0 | C20: =Assumptions!$B$61 -> 25200 | D20: =C20*Assumptions!$B$90 -> 20160 | E20: =C20*Assumptions!$B$92 -> 32760 | F20: =C20*12 -> 302400 | G20: =D20*12 -> 241920 | H20: =E20*12 -> 393120 | I20: Assumptions sheet — NEW v0.3 (DC-16; review finding v0.3-13)
A21: Courier/3PL data handling | B21: R1 | C21: =Assumptions!$B$52 -> 0 | D21: =C21*Assumptions!$B$90 -> 0 | E21: =C21*Assumptions!$B$92 -> 0 | F21: =C21*12 -> 0 | G21: =D21*12 -> 0 | H21: =E21*12 -> 0 | I21: Assumptions sheet — NEW v0.2; ₹0 ASSUMPTION (CON-32 / WP-35)
A22: AI consumption (Anthropic) | B22: R5 | C22: =Assumptions!$B$75 -> 49560 | D22: =C22*Assumptions!$B$90 -> 39648 | E22: =C22*Assumptions!$B$92 -> 64428 | F22: =C22*12 -> 594720 | G22: =D22*12 -> 475776 | H22: =E22*12 -> 773136 | I22: Assumptions sheet
A23: Optional native / extension upkeep | B23: R5 | C23: =Assumptions!$B$51 -> 40000 | D23: =C23*Assumptions!$B$90 -> 32000 | E23: =C23*Assumptions!$B$92 -> 52000 | F23: =C23*12 -> 480000 | G23: =D23*12 -> 384000 | H23: =E23*12 -> 624000 | I23: Assumptions sheet
A24: TOTAL OpEx — full parity (all lines) | C24: =SUM(C5:C23) -> 495760 | D24: =SUM(D5:D23) -> 396608 | E24: =SUM(E5:E23) -> 644488 | F24: =SUM(F5:F23) -> 5949120 | G24: =SUM(G5:G23) -> 4759296 | H24: =SUM(H5:H23) -> 7733856
A25: TOTAL OpEx — initial release (lines applicable ≤ R1) | C25: =SUMIFS(C5:C23,$B$5:$B$23,"R0")+SUMIFS(C5:C23,$B$5:$B$23,"R1") -> 406200 | D25: =SUMIFS(D5:D23,$B$5:$B$23,"R0")+SUMIFS(D5:D23,$B$5:$B$23,"R1") -> 324960 | E25: =SUMIFS(E5:E23,$B$5:$B$23,"R0")+SUMIFS(E5:E23,$B$5:$B$23,"R1") -> 528060 | F25: =SUMIFS(F5:F23,$B$5:$B$23,"R0")+SUMIFS(F5:F23,$B$5:$B$23,"R1") -> 4874400 | G25: =SUMIFS(G5:G23,$B$5:$B$23,"R0")+SUMIFS(G5:G23,$B$5:$B$23,"R1") -> 3899520 | H25: =SUMIFS(H5:H23,$B$5:$B$23,"R0")+SUMIFS(H5:H23,$B$5:$B$23,"R1") -> 6336720 | I25: Excludes AI consumption and native/extension upkeep (start R5); includes Ads API spend read (₹0), Shopify app and Courier/3PL line (R1)
A26: of which cloud subtotal | C26: =SUM(C5:C12) -> 129000
A27: 'Applies from release' (blue) drives which lines count toward the initial-release (R0+R1) OpEx and phased Year-1 on the TCO sheet.

Sheet TCO
A1: Total cost of ownership — cash basis; amortization shown as separate memo line (NOT added)
A2: INR. Build = labour + contingency + one-time non-labour + training. Cash TCO includes the 20% contingency as committed budget; it is shown separately in Build_Summary. OpEx from OpEx_Monthly (initial-release horizons use only lines applicable ≤R1). Low/base/high = scenario multipliers on Assumptions.
A4: Inputs pulled
A5: Initial bounded release build (labour + contingency) | B5: =Build_Summary!$E$19 -> 21060306
A6: Full approved parity build (labour + contingency) | B6: =Build_Summary!$E$12 -> 33124800
A7: One-time non-labour + training | B7: =Assumptions!$B$78+Assumptions!$B$79+Assumptions!$B$80 -> 650000
A8: Monthly OpEx (base) — full parity | B8: =OpEx_Monthly!$C$24 -> 495760
A9: Monthly OpEx (base) — initial release (lines ≤R1) | B9: =OpEx_Monthly!$C$25 -> 406200
A10: Scenario multipliers → | B10: =Assumptions!$B$90 -> 0.8 | C10: =Assumptions!$B$91 -> 1 | D10: =Assumptions!$B$92 -> 1.3
A12: A. Initial bounded release (R0+R1 + pro-rata ALL) — all build cash in month 0; OpEx lines ≤R1 only
A13: Horizon | B13: Low | C13: Base | D13: High | E13: Formula
A14: 12-month cash TCO | B14: =(B$5+B$7)*B$10+B$9*12*B$10 -> 21267765 | C14: =(B$5+B$7)*C$10+B$9*12*C$10 -> 26584706 | D14: =(B$5+B$7)*D$10+B$9*12*D$10 -> 34560117 | E14: (build + one-time) × mult + monthly OpEx × 12 × mult
A15: 24-month cash TCO | B15: =(B$5+B$7)*B$10+B$9*24*B$10 -> 25167285 | C15: =(B$5+B$7)*C$10+B$9*24*C$10 -> 31459106 | D15: =(B$5+B$7)*D$10+B$9*24*D$10 -> 40896837 | E15: (build + one-time) × mult + monthly OpEx × 24 × mult
A16: 36-month cash TCO | B16: =(B$5+B$7)*B$10+B$9*36*B$10 -> 29066805 | C16: =(B$5+B$7)*C$10+B$9*36*C$10 -> 36333506 | D16: =(B$5+B$7)*D$10+B$9*36*D$10 -> 47233557 | E16: (build + one-time) × mult + monthly OpEx × 36 × mult
A18: B. Full approved parity — all build cash in month 0; full OpEx
A19: Horizon | B19: Low | C19: Base | D19: High | E19: Formula
A20: 12-month cash TCO | B20: =(B$6+B$7)*B$10+B$8*12*B$10 -> 31779136 | C20: =(B$6+B$7)*C$10+B$8*12*C$10 -> 39723920 | D20: =(B$6+B$7)*D$10+B$8*12*D$10 -> 51641096 | E20: (build + one-time) × mult + monthly OpEx × 12 × mult
A21: 24-month cash TCO | B21: =(B$6+B$7)*B$10+B$8*24*B$10 -> 36538432 | C21: =(B$6+B$7)*C$10+B$8*24*C$10 -> 45673040 | D21: =(B$6+B$7)*D$10+B$8*24*D$10 -> 59374952 | E21: (build + one-time) × mult + monthly OpEx × 24 × mult
A22: 36-month cash TCO | B22: =(B$6+B$7)*B$10+B$8*36*B$10 -> 41297728 | C22: =(B$6+B$7)*C$10+B$8*36*C$10 -> 51622160 | D22: =(B$6+B$7)*D$10+B$8*36*D$10 -> 67108808 | E22: (build + one-time) × mult + monthly OpEx × 36 × mult
A24: C. Phased full parity — R0–R1 in year 1, R2–R3 in year 2, R4–R5 in year 3 (ALL WPs pro-rata by hours per year)
A25: Year | B25: Build cash in year (base) | C25: OpEx in year (base) | D25: Cumulative cash TCO (base) | E25: Formula
A26: Year 1 (R0+R1) | B26: =Build_Summary!$E$5+Build_Summary!$E$6+Build_Summary!$E$11*IF(SUM(Build_Summary!$B$5:$B$10)=0,0,(Build_Summary!$B$5+Build_Summary!$B$6)/SUM(Build_Summary!$B$5:$B$10))+B$7 -> 21710306 | C26: =B$9*12 -> 4874400 | D26: =B26+C26 -> 26584706 | E26: release totals incl. contingency + ALL × hours share + one-time; initial-release OpEx (≤R1) × 12
A27: Year 2 (R2+R3) | B27: =Build_Summary!$E$7+Build_Summary!$E$8+Build_Summary!$E$11*IF(SUM(Build_Summary!$B$5:$B$10)=0,0,(Build_Summary!$B$7+Build_Summary!$B$8)/SUM(Build_Summary!$B$5:$B$10)) -> 8602211.3 | C27: =B$9*12 -> 4874400 | D27: =D26+B27+C27 -> 40061317 | E27: release totals incl. contingency + ALL × hours share; OpEx lines ≤R1 × 12 (R5-only lines not yet live)
A28: Year 3 (R4+R5) | B28: =Build_Summary!$E$9+Build_Summary!$E$10+Build_Summary!$E$11*IF(SUM(Build_Summary!$B$5:$B$10)=0,0,(Build_Summary!$B$9+Build_Summary!$B$10)/SUM(Build_Summary!$B$5:$B$10)) -> 3462283.1 | C28: =B$8*12 -> 5949120 | D28: =D27+B28+C28 -> 49472720 | E28: release totals incl. contingency + ALL × hours share; full OpEx × 12
A29: Check: phased build sum = full parity build + one-time (phased TCO < B because Years 1–2 OpEx use the ≤R1 subset; phasing is illustrative — calendar is 62 weeks if sequential) | B29: =SUM(B26:B28) -> 33774800 | E29: =IF(ABS(B29-(B6+B7))<1,"OK — reconciles","CHECK") -> OK — reconciles
A30: Phased 36-month cash TCO — low / base / high | B30: =D28*B$10 -> 39578176 | C30: =D28*C$10 -> 49472720 | D30: =D28*D$10 -> 64314536
A32: MEMO — amortization (NOT cash, NOT added to TCO above)
A33: Horizon | B33: Approved CapEx | C33: Cumulative amortization | D33: Net book value | E33: Note
A34: 12 months | B34: =Accounting_Boundary!$C$22 -> 0 | C34: =MIN(Accounting_Boundary!$C$31*12,B34) -> 0 | D34: =B34-C34 -> 0 | E34: Straight-line over Assumptions amortization years, on approved CapEx only (default 0)
A35: 24 months | B35: =Accounting_Boundary!$C$22 -> 0 | C35: =MIN(Accounting_Boundary!$C$31*24,B35) -> 0 | D35: =B35-C35 -> 0 | E35: Straight-line over Assumptions amortization years, on approved CapEx only (default 0)
A36: 36 months | B36: =Accounting_Boundary!$C$22 -> 0 | C36: =MIN(Accounting_Boundary!$C$31*36,B36) -> 0 | D36: =B36-C36 -> 0 | E36: Straight-line over Assumptions amortization years, on approved CapEx only (default 0)

Sheet Accounting_Boundary
A1: Accounting boundary — CapEx-candidate (development) vs expensed, by WP category
A2: Candidate-qualifying % is a judgement INPUT per category (blue). Actual capitalization requires CFO approval; default approved % = 0.
A4: Category | B4: Hours | C4: Labour cost | D4: Candidate-qualifying % | E4: Candidate-qualifying cost | F4: Expensed cost | G4: Rationale (planning judgement — not accounting advice)
A5: Discovery | B5: =SUMIFS(WorkPackages!$E$4:$E$39,WorkPackages!$H$4:$H$39,"Discovery") -> 160 | C5: =SUMIFS(WorkPackages!$G$4:$G$39,WorkPackages!$H$4:$H$39,"Discovery") -> 560000 | D5: 0 | E5: =C5*D5 -> 0 | F5: =C5-E5 -> 560000 | G5: Research phase — expensed (IAS 38.54)
A6: Design | B6: =SUMIFS(WorkPackages!$E$4:$E$39,WorkPackages!$H$4:$H$39,"Design") -> 240 | C6: =SUMIFS(WorkPackages!$G$4:$G$39,WorkPackages!$H$4:$H$39,"Design") -> 480000 | D6: 0.8 | E6: =C6*D6 -> 384000 | F6: =C6-E6 -> 96000 | G6: UX design of the application — development; 20% exploratory
A7: Backend | B7: =SUMIFS(WorkPackages!$E$4:$E$39,WorkPackages!$H$4:$H$39,"Backend") -> 2700 | C7: =SUMIFS(WorkPackages!$G$4:$G$39,WorkPackages!$H$4:$H$39,"Backend") -> 6732000 | D7: 0.9 | E7: =C7*D7 -> 6058800 | F7: =C7-E7 -> 673200 | G7: Development of the asset; 10% spikes / rework (incl. WP-31 B2B module)
A8: Frontend | B8: =SUMIFS(WorkPackages!$E$4:$E$39,WorkPackages!$H$4:$H$39,"Frontend") -> 1260 | C8: =SUMIFS(WorkPackages!$G$4:$G$39,WorkPackages!$H$4:$H$39,"Frontend") -> 2844000 | D8: 0.9 | E8: =C8*D8 -> 2559600 | F8: =C8-E8 -> 284400 | G8: Development (incl. WP-33 mobile-first PWA shell)
A9: Financial engine | B9: =SUMIFS(WorkPackages!$E$4:$E$39,WorkPackages!$H$4:$H$39,"Financial engine") -> 1700 | C9: =SUMIFS(WorkPackages!$G$4:$G$39,WorkPackages!$H$4:$H$39,"Financial engine") -> 4376000 | D9: 0.9 | E9: =C9*D9 -> 3938400 | F9: =C9-E9 -> 437600 | G9: Development (incl. WP-32, WP-34, WP-36)
A10: Connector core | B10: =SUMIFS(WorkPackages!$E$4:$E$39,WorkPackages!$H$4:$H$39,"Connector core") -> 1580 | C10: =SUMIFS(WorkPackages!$G$4:$G$39,WorkPackages!$H$4:$H$39,"Connector core") -> 4108000 | D10: 0.9 | E10: =C10*D10 -> 3697200 | F10: =C10-E10 -> 410800 | G10: Development (incl. WP-35 Shopify cost completeness)
A11: Connector extended | B11: =SUMIFS(WorkPackages!$E$4:$E$39,WorkPackages!$H$4:$H$39,"Connector extended") -> 1120 | C11: =SUMIFS(WorkPackages!$G$4:$G$39,WorkPackages!$H$4:$H$39,"Connector extended") -> 2840000 | D11: 0.9 | E11: =C11*D11 -> 2556000 | F11: =C11-E11 -> 284000 | G11: Development (R5)
A12: Automation | B12: =SUMIFS(WorkPackages!$E$4:$E$39,WorkPackages!$H$4:$H$39,"Automation") -> 820 | C12: =SUMIFS(WorkPackages!$G$4:$G$39,WorkPackages!$H$4:$H$39,"Automation") -> 1968000 | D12: 0.9 | E12: =C12*D12 -> 1771200 | F12: =C12-E12 -> 196800 | G12: Development
A13: QA-security | B13: =SUMIFS(WorkPackages!$E$4:$E$39,WorkPackages!$H$4:$H$39,"QA-security") -> 640 | C13: =SUMIFS(WorkPackages!$G$4:$G$39,WorkPackages!$H$4:$H$39,"QA-security") -> 1152000 | D13: 0.5 | E13: =C13*D13 -> 576000 | F13: =C13-E13 -> 576000 | G13: Testing during development qualifies; UAT support & security review share expensed
A14: DevOps | B14: =SUMIFS(WorkPackages!$E$4:$E$39,WorkPackages!$H$4:$H$39,"DevOps") -> 320 | C14: =SUMIFS(WorkPackages!$G$4:$G$39,WorkPackages!$H$4:$H$39,"DevOps") -> 768000 | D14: 0.6 | E14: =C14*D14 -> 460800 | F14: =C14-E14 -> 307200 | G14: Environment build qualifies; run/operate share expensed
A15: Migration | B15: =SUMIFS(WorkPackages!$E$4:$E$39,WorkPackages!$H$4:$H$39,"Migration") -> 240 | C15: =SUMIFS(WorkPackages!$G$4:$G$39,WorkPackages!$H$4:$H$39,"Migration") -> 576000 | D15: 0 | E15: =C15*D15 -> 0 | F15: =C15-E15 -> 576000 | G15: Data conversion & documentation — expensed
A16: Training | B16: =SUMIFS(WorkPackages!$E$4:$E$39,WorkPackages!$H$4:$H$39,"Training") -> 0 | C16: =SUMIFS(WorkPackages!$G$4:$G$39,WorkPackages!$H$4:$H$39,"Training") -> 0 | D16: 0 | E16: =C16*D16 -> 0 | F16: =C16-E16 -> 0 | G16: Training — expensed (IAS 38.69)
A17: Leadership | B17: =SUMIFS(WorkPackages!$E$4:$E$39,WorkPackages!$H$4:$H$39,"Leadership") -> 400 | C17: =SUMIFS(WorkPackages!$G$4:$G$39,WorkPackages!$H$4:$H$39,"Leadership") -> 1200000 | D17: 0.3 | E17: =C17*D17 -> 360000 | F17: =C17-E17 -> 840000 | G17: Directly attributable PM share; change control / approvals expensed
A18: TOTAL labour | B18: =SUM(B5:B17) -> 11180 | C18: =SUM(C5:C17) -> 27604000 | D18: =IF(C18=0,0,E18/C18) -> 0.81009999 | E18: =SUM(E5:E17) -> 22362000 | F18: =SUM(F5:F17) -> 5242000 | G18: =IF(ABS(C18-Build_Summary!$C$12)<1,"OK — reconciles to Build_Summary","CHECK") -> OK — reconciles to Build_Summary
A20: Resulting classification (full parity)
A21: Capitalization approved % | C21: =Assumptions!$B$95 -> 0 | G21: Set on Assumptions after CFO review; default 0
A22: CapEx (approved) = candidate-qualifying × approved % | C22: =E18*C21 -> 0
A23: Expense = total labour − CapEx approved | C23: =C18-C22 -> 27604000
A24: Contingency reserve (committed budget; classified when drawn) | C24: =Build_Summary!$D$12 -> 5520800
A25: One-time non-labour (laptops/licences) — expensed or PPE per policy | C25: =Assumptions!$B$78 -> 400000
A26: Training — expensed | C26: =Assumptions!$B$79 -> 250000
A28: Amortization (only on approved CapEx)
A29: Amortization years | C29: =Assumptions!$B$23 -> 3
A30: Annual straight-line amortization | C30: =IF(C29=0,0,C22/C29) -> 0
A31: Monthly amortization | C31: =C30/12 -> 0
A33: Ind AS 38 / IAS 38 (para 57) — development costs may be capitalized only when ALL six criteria are demonstrated:
A34: 1) technical feasibility of completing the asset; 2) intention to complete and use it; 3) ability to use it; 4) how it will generate probable future economic benefits;
A35: 5) availability of adequate technical, financial and other resources to complete; 6) ability to measure attributable expenditure reliably.
A36: Research-phase (discovery), training, data migration/conversion, and post-implementation maintenance are expensed. Percentages above are planning judgements for a CFO / auditor review, not accounting advice.
A37: Cash TCO on the TCO sheet is unaffected by this classification; amortization is shown there as a separate memo line.

Sheet Build_vs_Buy
A1: Build vs buy — existing Sellerboard spend vs in-house app OpEx; payback on benefit threshold
A2: Benefit default 0 → payback shows 'N/A (benefit unproven)'. Excluded from both sides: ad spend, stock, fulfilment, GST.
A4: Item | B4: Monthly (INR) | C4: Annual (INR) | D4: Note
A5: Sellerboard (sellerboard.com) = accounts × USD/mo × FX | B5: =Assumptions!$B$85*Assumptions!$B$84*Assumptions!$B$22 -> 9828 | C5: =B5*12 -> 117936 | D5: OBSERVED: $39/mo Business plan on sellerboard.com; 3 accounts
A6: Sellerboard (sellerboard.io) = Shopify stores × USD/mo × FX | B6: =Assumptions!$B$87*Assumptions!$B$86*Assumptions!$B$22 -> 3276 | C6: =B6*12 -> 39312 | D6: ASSUMPTION: sellerboard.io plan unknown → $39/mo assumed; 1 Shopify store
A7: Sellerboard spend — total | B7: =B5+B6 -> 13104 | C7: =B7*12 -> 157248
A8: In-house app OpEx (base) — full parity | B8: =OpEx_Monthly!$C$24 -> 495760 | C8: =B8*12 -> 5949120 | D8: From OpEx_Monthly
A9: Monthly OpEx delta (app − Sellerboard) | B9: =B8-B7 -> 482656 | C9: =B9*12 -> 5791872 | D9: Positive = app costs more to run than Sellerboard
A10: Sellerboard spend as % of app OpEx | B10: =IF(B8=0,0,B7/B8) -> 0.026432145
A12: Payback
A13: Monthly benefit threshold (INR) — from Assumptions | B13: =Assumptions!$B$83 -> 0 | D13: Default 0 = unproven. Enter only evidenced margin gains / savings.
A14: Net monthly benefit = benefit − OpEx delta | B14: =B13-B9 -> -482656
A15: Payback (months) — initial bounded release | B15: =IF(B13<=0,"N/A (benefit unproven)",IF(B14<=0,"N/A (no net monthly benefit)",(Build_Summary!$E$19+Assumptions!$B$78+Assumptions!$B$79)/B14)) -> N/A (benefit unproven) | D15: Formula: (build incl. contingency + one-time) ÷ net monthly benefit
A16: Payback (months) — full parity | B16: =IF(B13<=0,"N/A (benefit unproven)",IF(B14<=0,"N/A (no net monthly benefit)",(Build_Summary!$E$12+Assumptions!$B$78+Assumptions!$B$79)/B14)) -> N/A (benefit unproven) | D16: Formula: (build incl. contingency + one-time) ÷ net monthly benefit
A17: Monthly benefit needed for 36-month payback (full parity) | B17: =(Build_Summary!$E$12+Assumptions!$B$78+Assumptions!$B$79)/36+B9 -> 1420844.9 | D17: Reference: benefit that would be required, not a forecast
A19: Excluded costs on both sides: advertising spend, inventory/stock purchases, fulfilment & shipping fees, marketplace commissions, GST, office overhead.
A20: Sellerboard replacement is not cost-driven at these figures: the app's OpEx alone exceeds the combined sellerboard.com + sellerboard.io subscription many times over; the case rests on evidenced benefits (data ownership, India-first fee taxonomy, unified Amazon + Shopify + B2B view, automation with maker-checker) that this sheet treats as unproven until entered.

